[2024-06-30T13:39:42.669+0000] {taskinstance.py:1979} INFO - Dependencies all met for dep_context=non-requeueable deps ti=<TaskInstance: dag_sentiment_analysis.extract_load manual__2024-06-30T13:39:40.046267+00:00 [queued]>
[2024-06-30T13:39:42.711+0000] {taskinstance.py:1979} INFO - Dependencies all met for dep_context=requeueable deps ti=<TaskInstance: dag_sentiment_analysis.extract_load manual__2024-06-30T13:39:40.046267+00:00 [queued]>
[2024-06-30T13:39:42.713+0000] {taskinstance.py:2193} INFO - Starting attempt 1 of 2
[2024-06-30T13:39:42.760+0000] {taskinstance.py:2217} INFO - Executing <Task(PythonOperator): extract_load> on 2024-06-30 13:39:40.046267+00:00
[2024-06-30T13:39:42.798+0000] {standard_task_runner.py:60} INFO - Started process 570 to run task
[2024-06-30T13:39:42.879+0000] {standard_task_runner.py:87} INFO - Running: ['***', 'tasks', 'run', 'dag_sentiment_analysis', 'extract_load', 'manual__2024-06-30T13:39:40.046267+00:00', '--job-id', '54', '--raw', '--subdir', 'DAGS_FOLDER/dag_sentiment_analysis.py', '--cfg-path', '/tmp/tmp6be_z5c1']
[2024-06-30T13:39:42.927+0000] {standard_task_runner.py:88} INFO - Job 54: Subtask extract_load
[2024-06-30T13:39:43.161+0000] {logging_mixin.py:188} WARNING - /home/***/.local/lib/python3.10/site-packages/***/settings.py:194 DeprecationWarning: The sql_alchemy_conn option in [core] has been moved to the sql_alchemy_conn option in [database] - the old setting has been used, but please update your config.
[2024-06-30T13:39:43.629+0000] {task_command.py:423} INFO - Running <TaskInstance: dag_sentiment_analysis.extract_load manual__2024-06-30T13:39:40.046267+00:00 [running]> on host a9ab29ad88be
[2024-06-30T13:39:44.079+0000] {taskinstance.py:2513} INFO - Exporting env vars: AIRFLOW_CTX_DAG_OWNER='de-team' AIRFLOW_CTX_DAG_ID='dag_sentiment_analysis' AIRFLOW_CTX_TASK_ID='extract_load' AIRFLOW_CTX_EXECUTION_DATE='2024-06-30T13:39:40.046267+00:00' AIRFLOW_CTX_TRY_NUMBER='1' AIRFLOW_CTX_DAG_RUN_ID='manual__2024-06-30T13:39:40.046267+00:00'
[2024-06-30T13:40:56.421+0000] {logging_mixin.py:188} INFO - SSL handshake failed: ac-mukte2i-shard-00-01.pn34g58.mongodb.net:27017: [SSL: TLSV1_ALERT_INTERNAL_ERROR] tlsv1 alert internal error (_ssl.c:1007) (configured timeouts: socketTimeoutMS: 60000.0ms, connectTimeoutMS: 60000.0ms),SSL handshake failed: ac-mukte2i-shard-00-00.pn34g58.mongodb.net:27017: [SSL: TLSV1_ALERT_INTERNAL_ERROR] tlsv1 alert internal error (_ssl.c:1007) (configured timeouts: socketTimeoutMS: 60000.0ms, connectTimeoutMS: 60000.0ms),SSL handshake failed: ac-mukte2i-shard-00-02.pn34g58.mongodb.net:27017: [SSL: TLSV1_ALERT_INTERNAL_ERROR] tlsv1 alert internal error (_ssl.c:1007) (configured timeouts: socketTimeoutMS: 60000.0ms, connectTimeoutMS: 60000.0ms), Timeout: 30s, Topology Description: <TopologyDescription id: 6681604936f81900d9cb85f1, topology_type: Unknown, servers: [<ServerDescription ('ac-mukte2i-shard-00-00.pn34g58.mongodb.net', 27017) server_type: Unknown, rtt: None, error=AutoReconnect('SSL handshake failed: ac-mukte2i-shard-00-00.pn34g58.mongodb.net:27017: [SSL: TLSV1_ALERT_INTERNAL_ERROR] tlsv1 alert internal error (_ssl.c:1007) (configured timeouts: socketTimeoutMS: 60000.0ms, connectTimeoutMS: 60000.0ms)')>, <ServerDescription ('ac-mukte2i-shard-00-01.pn34g58.mongodb.net', 27017) server_type: Unknown, rtt: None, error=AutoReconnect('SSL handshake failed: ac-mukte2i-shard-00-01.pn34g58.mongodb.net:27017: [SSL: TLSV1_ALERT_INTERNAL_ERROR] tlsv1 alert internal error (_ssl.c:1007) (configured timeouts: socketTimeoutMS: 60000.0ms, connectTimeoutMS: 60000.0ms)')>, <ServerDescription ('ac-mukte2i-shard-00-02.pn34g58.mongodb.net', 27017) server_type: Unknown, rtt: None, error=AutoReconnect('SSL handshake failed: ac-mukte2i-shard-00-02.pn34g58.mongodb.net:27017: [SSL: TLSV1_ALERT_INTERNAL_ERROR] tlsv1 alert internal error (_ssl.c:1007) (configured timeouts: socketTimeoutMS: 60000.0ms, connectTimeoutMS: 60000.0ms)')>]>
[2024-06-30T13:40:56.423+0000] {taskinstance.py:2731} ERROR - Task failed with exception
Traceback (most recent call last):
  File "/home/airflow/.local/lib/python3.10/site-packages/airflow/models/taskinstance.py", line 444, in _execute_task
    result = _execute_callable(context=context, **execute_callable_kwargs)
  File "/home/airflow/.local/lib/python3.10/site-packages/airflow/models/taskinstance.py", line 414, in _execute_callable
    return execute_callable(context=context, **execute_callable_kwargs)
  File "/home/airflow/.local/lib/python3.10/site-packages/airflow/operators/python.py", line 200, in execute
    return_value = self.execute_callable()
  File "/home/airflow/.local/lib/python3.10/site-packages/airflow/operators/python.py", line 217, in execute_callable
    return self.python_callable(*self.op_args, **self.op_kwargs)
  File "/opt/airflow/plugins/finnhub_mongodb_loader.py", line 7, in extract_load
    collection = mongodb_loader.load('news', 'finnhub_news')
  File "/opt/airflow/plugins/mongodb_loader.py", line 29, in load
    db = mongo_client[database]
TypeError: 'NoneType' object is not subscriptable
[2024-06-30T13:40:56.451+0000] {taskinstance.py:1149} INFO - Marking task as UP_FOR_RETRY. dag_id=dag_sentiment_analysis, task_id=extract_load, execution_date=20240630T133940, start_date=20240630T133942, end_date=20240630T134056
[2024-06-30T13:40:56.478+0000] {standard_task_runner.py:107} ERROR - Failed to execute job 54 for task extract_load ('NoneType' object is not subscriptable; 570)
[2024-06-30T13:40:56.535+0000] {local_task_job_runner.py:234} INFO - Task exited with return code 1
[2024-06-30T13:40:56.580+0000] {taskinstance.py:3312} INFO - 0 downstream tasks scheduled from follow-on schedule check
