[2024-06-30T13:53:36.996+0000] {taskinstance.py:1979} INFO - Dependencies all met for dep_context=non-requeueable deps ti=<TaskInstance: dag_sentiment_analysis.sa_load scheduled__2024-06-30T12:00:00+00:00 [queued]>
[2024-06-30T13:53:37.015+0000] {taskinstance.py:1979} INFO - Dependencies all met for dep_context=requeueable deps ti=<TaskInstance: dag_sentiment_analysis.sa_load scheduled__2024-06-30T12:00:00+00:00 [queued]>
[2024-06-30T13:53:37.016+0000] {taskinstance.py:2193} INFO - Starting attempt 2 of 2
[2024-06-30T13:53:37.042+0000] {taskinstance.py:2217} INFO - Executing <Task(PythonOperator): sa_load> on 2024-06-30 12:00:00+00:00
[2024-06-30T13:53:37.065+0000] {standard_task_runner.py:60} INFO - Started process 215 to run task
[2024-06-30T13:53:37.071+0000] {standard_task_runner.py:87} INFO - Running: ['***', 'tasks', 'run', 'dag_sentiment_analysis', 'sa_load', 'scheduled__2024-06-30T12:00:00+00:00', '--job-id', '60', '--raw', '--subdir', 'DAGS_FOLDER/dag_sentiment_analysis.py', '--cfg-path', '/tmp/tmp630m0ol_']
[2024-06-30T13:53:37.075+0000] {standard_task_runner.py:88} INFO - Job 60: Subtask sa_load
[2024-06-30T13:53:37.113+0000] {logging_mixin.py:188} WARNING - /home/***/.local/lib/python3.10/site-packages/***/settings.py:194 DeprecationWarning: The sql_alchemy_conn option in [core] has been moved to the sql_alchemy_conn option in [database] - the old setting has been used, but please update your config.
[2024-06-30T13:53:37.207+0000] {task_command.py:423} INFO - Running <TaskInstance: dag_sentiment_analysis.sa_load scheduled__2024-06-30T12:00:00+00:00 [running]> on host 7c9851f56a65
[2024-06-30T13:53:37.434+0000] {taskinstance.py:2513} INFO - Exporting env vars: AIRFLOW_CTX_DAG_OWNER='de-team' AIRFLOW_CTX_DAG_ID='dag_sentiment_analysis' AIRFLOW_CTX_TASK_ID='sa_load' AIRFLOW_CTX_EXECUTION_DATE='2024-06-30T12:00:00+00:00' AIRFLOW_CTX_TRY_NUMBER='2' AIRFLOW_CTX_DAG_RUN_ID='scheduled__2024-06-30T12:00:00+00:00'
[2024-06-30T13:53:59.301+0000] {taskinstance.py:2731} ERROR - Task failed with exception
Traceback (most recent call last):
  File "/home/airflow/.local/lib/python3.10/site-packages/airflow/models/taskinstance.py", line 444, in _execute_task
    result = _execute_callable(context=context, **execute_callable_kwargs)
  File "/home/airflow/.local/lib/python3.10/site-packages/airflow/models/taskinstance.py", line 414, in _execute_callable
    return execute_callable(context=context, **execute_callable_kwargs)
  File "/home/airflow/.local/lib/python3.10/site-packages/airflow/operators/python.py", line 200, in execute
    return_value = self.execute_callable()
  File "/home/airflow/.local/lib/python3.10/site-packages/airflow/operators/python.py", line 217, in execute_callable
    return self.python_callable(*self.op_args, **self.op_kwargs)
  File "/opt/airflow/plugins/sentiment_analysis_loader.py", line 7, in run
    db = mongodb_loader.get_data("news", "finnhub_news")
  File "/opt/airflow/plugins/mongodb_loader.py", line 39, in get_data
    mongo_client = get_mongo_client(mongo_uri)
  File "/opt/airflow/plugins/mongodb_loader.py", line 8, in get_mongo_client
    client = pymongo.MongoClient(mongo_uri)
  File "/home/airflow/.local/lib/python3.10/site-packages/pymongo/mongo_client.py", line 774, in __init__
    res = uri_parser.parse_uri(
  File "/home/airflow/.local/lib/python3.10/site-packages/pymongo/uri_parser.py", line 543, in parse_uri
    dns_options = dns_resolver.get_options()
  File "/home/airflow/.local/lib/python3.10/site-packages/pymongo/srv_resolver.py", line 99, in get_options
    raise ConfigurationError(str(exc)) from None
pymongo.errors.ConfigurationError: The resolution lifetime expired after 21.122 seconds: Server Do53:127.0.0.11@53 answered The DNS operation timed out.; Server Do53:127.0.0.11@53 answered The DNS operation timed out.; Server Do53:127.0.0.11@53 answered The DNS operation timed out.; Server Do53:127.0.0.11@53 answered The DNS operation timed out.; Server Do53:127.0.0.11@53 answered The DNS operation timed out.; Server Do53:127.0.0.11@53 answered The DNS operation timed out.; Server Do53:127.0.0.11@53 answered The DNS operation timed out.
[2024-06-30T13:53:59.332+0000] {taskinstance.py:1149} INFO - Marking task as FAILED. dag_id=dag_sentiment_analysis, task_id=sa_load, execution_date=20240630T120000, start_date=20240630T135336, end_date=20240630T135359
[2024-06-30T13:53:59.364+0000] {standard_task_runner.py:107} ERROR - Failed to execute job 60 for task sa_load (The resolution lifetime expired after 21.122 seconds: Server Do53:127.0.0.11@53 answered The DNS operation timed out.; Server Do53:127.0.0.11@53 answered The DNS operation timed out.; Server Do53:127.0.0.11@53 answered The DNS operation timed out.; Server Do53:127.0.0.11@53 answered The DNS operation timed out.; Server Do53:127.0.0.11@53 answered The DNS operation timed out.; Server Do53:127.0.0.11@53 answered The DNS operation timed out.; Server Do53:127.0.0.11@53 answered The DNS operation timed out.; 215)
[2024-06-30T13:53:59.409+0000] {local_task_job_runner.py:234} INFO - Task exited with return code 1
[2024-06-30T13:53:59.430+0000] {taskinstance.py:3312} INFO - 0 downstream tasks scheduled from follow-on schedule check
